Workbook

Sheet About
A1: CSDS 2 Climate Disclosure Assessment Framework (Portfolio Version)
A3: A checklist for scoring a company's climate or sustainability report against the Canadian Sustainability Disclosure Standard 2 (CSDS 2).
A4: Built from my work benchmarking 100+ TSX-listed companies at the Canada Climate Law Initiative. Requirement wording is paraphrased.
A5: No research results are included. The example column scores a fictional company to show how the checklist is used.
A7: Sheets
A8: Scope Rules: what counts as an eligible report and how edge cases are handled.
A9: Checklist: CSDS 2 requirements by pillar, scored Y or N with page evidence.
A10: Summary: disclosure rate by pillar, calculated from the checklist.
A11: Judgment Calls: recurring edge cases and how each was resolved.
A13: Prepared by Harshita Sadhna

Sheet Scope Rules
A1: Scope and scoring rules
A3: Rule | B3: Detail
A4: Eligible report | B4: Climate or sustainability report published in 2026 that covers fiscal 2025 data
A5: Older data | B5: Reports covering 2024 data are recorded but not scored
A6: Non-calendar years | B6: Accepted if the fiscal year ends in 2025; fiscal period noted
A7: Multiple documents | B7: Sustainability report, separate climate or TCFD report and data supplements are read together
A8: Scoring | B8: Y only where the report itself discloses the item; intentions or future commitments score N
A9: Evidence | B9: Page reference recorded for every Y so a reviewer can verify it
A10: Framework references | B10: Note whether the report cites TCFD, ISSB, SASB or CSDS, and whether a mapping index is included

Sheet Checklist
A1: CSDS 2 checklist (requirements paraphrased)
A2: Example column scores a fictional company, 'Example Co.'. Use Y or N only.
A4: Pillar | B4: Para. | C4: Requirement | D4: Example Co. (Y/N) | E4: Page | F4: Evidence / note
A5: Governance | B5: 6(a) | C5: Board or committee overseeing climate risks and opportunities is identified | D5: Y | E5: 12 | F5: Sustainability committee of the board
A6: Governance | B6: 6(a)(i) | C6: Climate responsibilities appear in mandates or terms of reference | D6: Y | E6: 12
A7: Governance | B7: 6(a)(ii) | C7: How the board ensures it has the right climate skills | D7: N
A8: Governance | B8: 6(a)(iii) | C8: How and how often the board is informed about climate issues | D8: Y | E8: 13 | F8: Quarterly updates
A9: Governance | B9: 6(a)(iv) | C9: Climate considered in strategy, major transactions and risk policy | D9: N
A10: Governance | B10: 6(a)(v) | C10: Board oversees climate target-setting and progress | D10: Y | E10: 13
A11: Governance | B11: 6(b)(i) | C11: Management role or committee for climate is named | D11: Y | E11: 14
A12: Governance | B12: 6(b)(ii) | C12: Controls and procedures supporting oversight are described | D12: N
A13: Strategy | B13: 10(a) | C13: Climate risks and opportunities are described | D13: Y | E13: 18
A14: Strategy | B14: 10(b) | C14: Each risk classified as physical or transition | D14: Y | E14: 18
A15: Strategy | B15: 10(c) | C15: Time horizon given for each risk and opportunity | D15: N
A16: Strategy | B16: 10(d) | C16: Short, medium and long term are defined | D16: N
A17: Strategy | B17: 13(a) | C17: Effects on business model and value chain | D17: Y | E17: 19
A18: Strategy | B18: 13(b) | C18: Where in the value chain risks are concentrated | D18: N
A19: Strategy | B19: 14(a) | C19: Response in strategy: business model, mitigation and adaptation | D19: Y | E19: 20
A20: Strategy | B20: 14(a)(iv) | C20: Transition plan, including key assumptions | D20: N
A21: Strategy | B21: 14(b) | C21: How these activities are resourced | D21: N
A22: Strategy | B22: 14(c) | C22: Progress on plans disclosed in earlier periods | D22: Y | E22: 21
A23: Financial effects | B23: 15(a) | C23: Current financial effects of climate risks and opportunities | D23: N
A24: Financial effects | B24: 15(b) | C24: Anticipated financial effects over time | D24: N
A25: Financial effects | B25: 16(c)(i) | C25: Investment and disposal plans linked to climate strategy | D25: N
A26: Financial effects | B26: 21 | C26: If not quantified, reason given and qualitative effects described | D26: N
A27: Resilience | B27: 22(a) | C27: Climate resilience assessment and its implications | D27: N
A28: Resilience | B28: 22(b)(i) | C28: Scenarios used, including one aligned with the Paris Agreement | D28: N
A29: Resilience | B29: 22(b)(ii) | C29: Key assumptions in scenario analysis | D29: N
A30: Risk management | B30: 25(a) | C30: Process to identify, assess and prioritize climate risks | D30: Y | E30: 24
A31: Risk management | B31: 25(a)(v) | C31: How climate risks are monitored | D31: Y | E31: 24
A32: Risk management | B32: 25(b) | C32: Process for climate opportunities | D32: N
A33: Risk management | B33: 25(c) | C33: Integration with overall risk management | D33: Y | E33: 25 | F33: Enterprise risk register
A34: Metrics | B34: 29(a)(i)(1) | C34: Scope 1 emissions disclosed | D34: Y | E34: 30
A35: Metrics | B35: 29(a)(i)(2) | C35: Scope 2 emissions disclosed | D35: Y | E35: 30 | F35: Location-based
A36: Metrics | B36: 29(a)(i)(3) | C36: Scope 3 emissions disclosed | D36: N | F36: Commits to Scope 3 next year: scored N
A37: Metrics | B37: 29(a)(ii) | C37: Measured under the GHG Protocol | D37: Y | E37: 31
A38: Metrics | B38: 29(a)(iii) | C38: Measurement approach, inputs and assumptions explained | D38: Y | E38: 31
A39: Metrics | B39: 29(a)(v) | C39: Location-based Scope 2 provided | D39: Y | E39: 30
A40: Metrics | B40: 29(a)(vi) | C40: Scope 3 categories included are listed | D40: N
A41: Metrics | B41: 29(b)-(c) | C41: Assets or activities exposed to transition and physical risks | D41: N
...

Sheet Summary
A1: Disclosure rate by pillar (Example Co.)
A3: Pillar | B3: Requirements | C3: Disclosed (Y) | D3: Rate
A4: Governance | B4: =COUNTIF(Checklist!$A$5:$A$49,A4) -> 8 | C4: =COUNTIFS(Checklist!$A$5:$A$49,A4,Checklist!$D$5:$D$49,"Y") -> 5 | D4: =IF(B4=0,0,C4/B4) -> 0.625
A5: Strategy | B5: =COUNTIF(Checklist!$A$5:$A$49,A5) -> 10 | C5: =COUNTIFS(Checklist!$A$5:$A$49,A5,Checklist!$D$5:$D$49,"Y") -> 5 | D5: =IF(B5=0,0,C5/B5) -> 0.5
A6: Financial effects | B6: =COUNTIF(Checklist!$A$5:$A$49,A6) -> 4 | C6: =COUNTIFS(Checklist!$A$5:$A$49,A6,Checklist!$D$5:$D$49,"Y") -> 0 | D6: =IF(B6=0,0,C6/B6) -> 0
A7: Resilience | B7: =COUNTIF(Checklist!$A$5:$A$49,A7) -> 3 | C7: =COUNTIFS(Checklist!$A$5:$A$49,A7,Checklist!$D$5:$D$49,"Y") -> 0 | D7: =IF(B7=0,0,C7/B7) -> 0
A8: Risk management | B8: =COUNTIF(Checklist!$A$5:$A$49,A8) -> 4 | C8: =COUNTIFS(Checklist!$A$5:$A$49,A8,Checklist!$D$5:$D$49,"Y") -> 3 | D8: =IF(B8=0,0,C8/B8) -> 0.75
A9: Metrics | B9: =COUNTIF(Checklist!$A$5:$A$49,A9) -> 11 | C9: =COUNTIFS(Checklist!$A$5:$A$49,A9,Checklist!$D$5:$D$49,"Y") -> 6 | D9: =IF(B9=0,0,C9/B9) -> 0.54545455
A10: Targets | B10: =COUNTIF(Checklist!$A$5:$A$49,A10) -> 5 | C10: =COUNTIFS(Checklist!$A$5:$A$49,A10,Checklist!$D$5:$D$49,"Y") -> 3 | D10: =IF(B10=0,0,C10/B10) -> 0.6
A11: Overall | B11: =SUM(B4:B10) -> 45 | C11: =SUM(C4:C10) -> 22 | D11: =C11/B11 -> 0.48888889

Sheet Judgment Calls
A1: Recurring edge cases and how they were scored
A3: Situation | B3: How it was handled | C3: Why
A4: Report published in 2026 but covering 2024 data | B4: Recorded, not scored | C4: Scope rule requires 2025 data
A5: Company removed environmental disclosures citing Bill C-59 | B5: Recorded as no eligible report; reason noted | C5: Shows how the Competition Act changes affected disclosure
A6: Broad safe-harbour disclaimer over emissions figures | B6: Scored on content, disclaimer noted | C6: Disclaimer does not remove the disclosure, but users should know
A7: Document is a performance summary, not a full report | B7: Not treated as a full report | C7: Company itself describes it as a summary
A8: ESG policy with commitments but no data | B8: Scored N throughout | C8: Forward-looking commitments are not disclosures
A9: Climate content split across several documents | B9: All documents read together, each linked | C9: Avoids under-scoring companies with separate TCFD reports
A10: Report cites TCFD or ISSB and includes an index | B10: Index used to locate items, each item still verified in the text | C10: An index entry alone is not evidence
A11: Environmental data one year older than governance data | B11: Metrics scored N for 2025, note added | C11: Data year must match the reporting period
