Workbook

Sheet About
A1: GHG Inventory Model: Textile Manufacturer (Portfolio Version)
A3: Company: Northline Knitwear (fictional). All inputs are fictional and were created for this portfolio.
A4: The methodology, boundaries, assumptions and emission factors reflect the original client project.
A5: Standard: GHG Protocol Corporate Standard, operational control approach. Reporting year: fictional FY2024.
A7: How to read this workbook
A8: Inputs: all activity data. Blue text = hardcoded input. Change any input and every total updates.
A9: Boundaries: which Scope 1, 2 and 3 categories are included, and why others are excluded.
A10: Calculations: activity x emission factor for each source. Green text = link to Inputs.
A11: Summary: totals by scope and category, with charts.
A12: Factors & Sources: every emission factor used and where it comes from.
A13: Prepared by Harshita Sadhna

Sheet Inputs
A1: Activity inputs (fictional)
A3: Month | B3: Natural gas (m3) | C3: Electricity (kWh)
A4: Jan | B4: 6900 | C4: 52000
A5: Feb | B5: 6200 | C5: 49500
A6: Mar | B6: 5100 | C6: 53800
A7: Apr | B7: 3300 | C7: 52600
A8: May | B8: 1600 | C8: 55200
A9: Jun | B9: 700 | C9: 57900
A10: Jul | B10: 400 | C10: 60400
A11: Aug | B11: 400 | C11: 59800
A12: Sep | B12: 900 | C12: 54100
A13: Oct | B13: 2600 | C13: 52900
A14: Nov | B14: 4700 | C14: 50300
A15: Dec | B15: 6100 | C15: 51500
A16: Total | B16: =SUM(B4:B15) -> 38900 | C16: =SUM(C4:C15) -> 650000
A18: Input | B18: Value | C18: Unit | D18: Note
A19: Fleet fuel spend | B19: 9800 | C19: USD | D19: No fuel records; spend-based estimate
A20: Total yarn purchased | B20: 1000000 | C20: kg | D20: Annual purchases
A21: Share sourced from India | B21: 0.5 | C21: % | D21: Equal split by fibre assumed within each country
A22: Share sourced from China | B22: 0.35 | C22: %
A23: Share sourced from US | B23: 0.15 | C23: %
A24: Cotton share of yarn | B24: 0.58 | C24: % | D24: Poly-cotton blend split into fibres
A25: Polyester share of yarn | B25: 0.42 | C25: %
A26: Polyester fabric purchased | B26: 100000 | C26: kg | D26: Imported from China
A27: Sea distance India port to West Coast | B27: 17618 | C27: km | D27: Nearest major export hub assumed
A28: Sea distance China port to West Coast | B28: 9464 | C28: km
A29: Sea distance US port to West Coast | B29: 2152 | C29: km
A30: Rail distance port to facility city | B30: 4000 | C30: km
A31: Truck distance rail yard to facility | B31: 35 | C31: km | D31: Heavy-duty truck assumed
A32: Yarn shipped to customers | B32: 450000 | C32: kg
A33: Fabric shipped to customers | B33: 100000 | C33: kg
A34: Share of shipments to US | B34: 0.7 | C34: % | D34: Customer addresses unknown; average distance
A35: Average distance to US customers | B35: 1833 | C35: km
A36: Share of shipments to Quebec | B36: 0.1 | C36: %
A37: Average distance to Quebec | B37: 772 | C37: km
A38: Share of shipments within Ontario | B38: 0.1 | C38: %
A39: Average distance within Ontario | B39: 50 | C39: km
A40: Share of shipments to Alberta | B40: 0.1 | C40: %
A41: Average distance to Alberta | B41: 3400 | C41: km
A42: Employees | B42: 35 | C42: people
...

Sheet Boundaries
A1: Operational boundary
A3: Scope | B3: Category | C3: Included? | D3: Reason
A4: Scope 1 | B4: Stationary combustion | C4: Yes | D4: Natural gas used at the knitting facility; monthly utility bills
A5: Scope 1 | B5: Mobile combustion | C5: Yes | D5: Company-owned vehicles; spend-based estimate as no fuel logs exist
A6: Scope 1 | B6: Fugitive emissions | C6: No | D6: No refrigerants or industrial gases used in operations
A7: Scope 2 | B7: Purchased electricity | C7: Yes | D7: Knitting facility electricity; monthly utility bills
A8: Scope 3 | B8: 1 Purchased goods and services | C8: Yes | D8: Yarn by fibre and sourcing country, and purchased fabric; activity-based
A9: Scope 3 | B9: 2 Capital goods | C9: No | D9: No data on machinery and equipment purchases
A10: Scope 3 | B10: 3 Fuel- and energy-related activities | C10: No | D10: Not material; energy use already covered in Scopes 1 and 2
A11: Scope 3 | B11: 4 Upstream transportation | C11: Yes | D11: Inbound sea, rail and truck freight; tonne-km method
A12: Scope 3 | B12: 5 Waste from operations | C12: No | D12: Waste data exists but is not tracked; recommended for next cycle
A13: Scope 3 | B13: 6 Business travel | C13: Yes | D13: Flights only; hotels and ground transport excluded
A14: Scope 3 | B14: 7 Employee commuting | C14: Yes | D14: Commute mode split by employee
... A20: Scope 3 | B20: 13 to 15 | C20: No | D20: Not applicable: no downstream leased assets, franchises or investments

Sheet Factors & Sources
A1: Emission factors
A3: Factor | B3: Value | C3: Unit | D3: Source
A4: Natural gas | B4: 0.001921 | C4: tCO2e per m3 | D4: Environment and Climate Change Canada, National Inventory Report (2024)
A5: Ontario grid electricity | B5: 3e-05 | C5: tCO2e per kWh | D5: Environment and Climate Change Canada, National Inventory Report (2024)
A6: Fleet fuel (spend-based) | B6: 0.00027 | C6: tCO2e per USD | D6: US EPA Supply Chain GHG Emission Factors v1.3 by NAICS-6
A7: Cotton yarn, India | B7: 3.7 | C7: tCO2e per tonne | D7: Peer-reviewed LCA literature (see References)
A8: Cotton yarn, China | B8: 3.53 | C8: tCO2e per tonne | D8: Peer-reviewed LCA literature (see References)
A9: Cotton yarn, US | B9: 3.43 | C9: tCO2e per tonne | D9: Peer-reviewed LCA literature (see References)
A10: Polyester yarn | B10: 6.8 | C10: tCO2e per tonne | D10: Peer-reviewed LCA literature (see References)
A11: Polyester fabric | B11: 25.7 | C11: tCO2e per tonne | D11: Peer-reviewed LCA literature (see References)
A12: Sea freight | B12: 0.00826 | C12: kgCO2e per tonne-km | D12: Original project factor set
A13: Rail freight | B13: 0.01194 | C13: kgCO2e per tonne-km | D13: CN Carbon Calculator emission factors
A14: Heavy-duty truck | B14: 0.07392 | C14: kgCO2e per tonne-km | D14: Original project factor set
A15: Car, per vehicle-km | B15: 0.16391 | C15: kgCO2e per km | D15: ICCT Canada fleet data
... A17: Medium-haul flight | B17: 0.0812 | C17: kgCO2e per pkm | D17: BC Methodology for Quantifying GHG Emissions (2024)
A20: References
A21: Fois, F. et al. (2025). Environmental impacts of cotton and polyester textile management strategies. Environmental Impact Assessment Review, 116, 108088.
A22: Environment and Climate Change Canada (2024). National Inventory Report. publications.gc.ca/collections/collection_2024/eccc/En84-294-2024-eng.pdf
A23: US EPA. Supply Chain Greenhouse Gas Emission Factors v1.3 by NAICS-6. catalog.data.gov
A24: Journal of Cleaner Production: sciencedirect.com/science/article/pii/S0959652614006702
A25: sciencedirect.com/science/article/pii/S266701002500006X
A26: CN Carbon Calculator Emission Factors. cn.ca
A27: ICCT (2018). Canada CAFE fleet data. theicct.org
A28: Government of BC (2024). Methodology for Quantifying Greenhouse Gas Emissions.
A30: Note: emission factors were carried over from the original analysis. Check each against the latest published version before reuse.

Sheet Calculations
A1: Emissions calculations: activity x emission factor
A3: Scope | B3: Source | C3: Activity | D3: Unit | E3: Factor | F3: Factor value | G3: tCO2e
A4: Scope 1 | B4: Natural gas, knitting facility | C4: =Inputs!B16 -> 38900 | D4: m3 | E4: Natural gas | F4: ='Factors & Sources'!$B$4 -> 0.001921 | G4: =C4*F4 -> 74.7269
A5: Scope 1 | B5: Company-owned vehicles | C5: =Inputs!$B$19 -> 9800 | D5: USD | E5: Fleet fuel (spend-based) | F5: ='Factors & Sources'!$B$6 -> 0.00027 | G5: =C5*F5 -> 2.646
A6: Scope 2 | B6: Purchased electricity | C6: =Inputs!C16 -> 650000 | D6: kWh | E6: Ontario grid electricity | F6: ='Factors & Sources'!$B$5 -> 3e-05 | G6: =C6*F6 -> 19.5
A7: Scope 3 | B7: Cat 1: Cotton yarn, India | C7: =Inputs!$B$20*Inputs!$B$21*Inputs!$B$24/1000 -> 290 | D7: tonnes | E7: Cotton yarn, India | F7: ='Factors & Sources'!$B$7 -> 3.7 | G7: =C7*F7 -> 1073
A8: Scope 3 | B8: Cat 1: Cotton yarn, China | C8: =Inputs!$B$20*Inputs!$B$22*Inputs!$B$24/1000 -> 203 | D8: tonnes | E8: Cotton yarn, China | F8: ='Factors & Sources'!$B$8 -> 3.53 | G8: =C8*F8 -> 716.59
A9: Scope 3 | B9: Cat 1: Cotton yarn, US | C9: =Inputs!$B$20*Inputs!$B$23*Inputs!$B$24/1000 -> 87 | D9: tonnes | E9: Cotton yarn, US | F9: ='Factors & Sources'!$B$9 -> 3.43 | G9: =C9*F9 -> 298.41
A10: Scope 3 | B10: Cat 1: Polyester yarn, India | C10: =Inputs!$B$20*Inputs!$B$21*Inputs!$B$25/1000 -> 210 | D10: tonnes | E10: Polyester yarn | F10: ='Factors & Sources'!$B$10 -> 6.8 | G10: =C10*F10 -> 1428
A11: Scope 3 | B11: Cat 1: Polyester yarn, China | C11: =Inputs!$B$20*Inputs!$B$22*Inputs!$B$25/1000 -> 147 | D11: tonnes | E11: Polyester yarn | F11: ='Factors & Sources'!$B$10 -> 6.8 | G11: =C11*F11 -> 999.6
A12: Scope 3 | B12: Cat 1: Polyester yarn, US | C12: =Inputs!$B$20*Inputs!$B$23*Inputs!$B$25/1000 -> 63 | D12: tonnes | E12: Polyester yarn | F12: ='Factors & Sources'!$B$10 -> 6.8 | G12: =C12*F12 -> 428.4
A13: Scope 3 | B13: Cat 1: Polyester fabric | C13: =Inputs!$B$26/1000 -> 100 | D13: tonnes | E13: Polyester fabric | F13: ='Factors & Sources'!$B$11 -> 25.7 | G13: =C13*F13 -> 2570
A14: Scope 3 | B14: Cat 4: Inbound sea freight | C14: =(Inputs!$B$20*Inputs!$B$21*Inputs!$B$27+Inputs!$B$20*Inputs!$B$22*Inputs!$B$28+Inputs!$B$20*Inputs!$B$23*Inputs!$B$29+Inputs!$B$26*Inputs!$B$28)/1000 -> 13390600 | D14: tonne-km | E14: Sea freight | F14: ='Factors & Sources'!$B$12 -> 0.00826 | G14: =C14*F14/1000 -> 110.60636
A15: Scope 3 | B15: Cat 4: Inbound rail freight | C15: =(Inputs!$B$20+Inputs!$B$26)/1000*Inputs!$B$30 -> 4400000 | D15: tonne-km | E15: Rail freight | F15: ='Factors & Sources'!$B$13 -> 0.01194 | G15: =C15*F15/1000 -> 52.536
A16: Scope 3 | B16: Cat 4: Inbound truck freight | C16: =(Inputs!$B$20+Inputs!$B$26)/1000*Inputs!$B$31 -> 38500 | D16: tonne-km | E16: Heavy-duty truck | F16: ='Factors & Sources'!$B$14 -> 0.07392 | G16: =C16*F16/1000 -> 2.84592
A17: Scope 3 | B17: Cat 9: Outbound truck to customers | C17: =(Inputs!$B$32+Inputs!$B$33)/1000*(Inputs!$B$34*Inputs!$B$35+Inputs!$B$36*Inputs!$B$37+Inputs!$B$38*Inputs!$B$39+Inputs!$B$40*Inputs!$B$41) -> 937915 | D17: tonne-km | E17: Heavy-duty truck | F17: ='Factors & Sources'!$B$14 -> 0.07392 | G17: =C17*F17/1000 -> 69.330677
A18: Scope 3 | B18: Cat 7: Commuting, drive alone | C18: =Inputs!$B$45*Inputs!$B$44*Inputs!$B$43 -> 50400 | D18: vehicle-km | E18: Car, per vehicle-km | F18: ='Factors & Sources'!$B$15 -> 0.16391 | G18: =C18*F18/1000 -> 8.261064
A19: Scope 3 | B19: Cat 7: Commuting, carpool | C19: =Inputs!$B$46/2*Inputs!$B$44*Inputs!$B$43 -> 21600 | D19: vehicle-km | E19: Car, per vehicle-km | F19: ='Factors & Sources'!$B$15 -> 0.16391 | G19: =C19*F19/1000 -> 3.540456
A20: Scope 3 | B20: Cat 7: Commuting, transit | C20: =Inputs!$B$47*Inputs!$B$44*Inputs!$B$43 -> 158400 | D20: passenger-km | E20: Transit, per passenger-km | F20: ='Factors & Sources'!$B$16 -> 0.043496 | G20: =C20*F20/1000 -> 6.8897664
A21: Scope 3 | B21: Cat 6: Business travel, flights | C21: =Inputs!$B$48*Inputs!$B$49 -> 62000 | D21: passenger-km | E21: Medium-haul flight | F21: ='Factors & Sources'!$B$17 -> 0.0812 | G21: =C21*F21/1000 -> 5.0344
B23: Total | G23: =SUM(G4:G21) -> 7869.9175

Sheet Summary
A1: Summary
A3: Scope | B3: tCO2e | C3: Share
A4: Scope 1 | B4: =SUMIF(Calculations!$A$4:$A$21,A4,Calculations!$G$4:$G$21) -> 77.3729 | C4: =B4/$B$7 -> 0.0098314753
A5: Scope 2 | B5: =SUMIF(Calculations!$A$4:$A$21,A5,Calculations!$G$4:$G$21) -> 19.5 | C5: =B5/$B$7 -> 0.0024777896
A6: Scope 3 | B6: =SUMIF(Calculations!$A$4:$A$21,A6,Calculations!$G$4:$G$21) -> 7773.0446 | C6: =B6/$B$7 -> 0.98769074
A7: Total | B7: =SUM(B4:B6) -> 7869.9175
A9: Scope 3 category | B9: tCO2e | C9: Share of Scope 3
A10: Cat 1: Cotton yarn | B10: =SUMIF(Calculations!$B$4:$B$21,"Cat 1: Cotton*",Calculations!$G$4:$G$21) -> 2088 | C10: =B10/$B$6 -> 0.26862061
A11: Cat 1: Polyester yarn | B11: =SUMIF(Calculations!$B$4:$B$21,"Cat 1: Polyester yarn*",Calculations!$G$4:$G$21) -> 2856 | C11: =B11/$B$6 -> 0.36742359
A12: Cat 1: Polyester fabric | B12: =SUMIF(Calculations!$B$4:$B$21,"Cat 1: Polyester fabric",Calculations!$G$4:$G$21) -> 2570 | C12: =B12/$B$6 -> 0.33062977
A13: Cat 4: Upstream transport | B13: =SUMIF(Calculations!$B$4:$B$21,"Cat 4*",Calculations!$G$4:$G$21) -> 165.98828 | C13: =B13/$B$6 -> 0.021354345
A14: Cat 9: Downstream transport | B14: =SUMIF(Calculations!$B$4:$B$21,"Cat 9*",Calculations!$G$4:$G$21) -> 69.330677 | C14: =B14/$B$6 -> 0.008919372
A15: Cat 7: Employee commuting | B15: =SUMIF(Calculations!$B$4:$B$21,"Cat 7*",Calculations!$G$4:$G$21) -> 18.691286 | C15: =B15/$B$6 -> 0.0024046287
A16: Cat 6: Business travel | B16: =SUMIF(Calculations!$B$4:$B$21,"Cat 6*",Calculations!$G$4:$G$21) -> 5.0344 | C16: =B16/$B$6 -> 0.00064767414
A19: Yarn emissions by country | B19: Cotton tCO2e | C19: Polyester tCO2e
A20: India | B20: =SUMIF(Calculations!$B$4:$B$21,"Cat 1: Cotton yarn, India",Calculations!$G$4:$G$21) -> 1073 | C20: =SUMIF(Calculations!$B$4:$B$21,"Cat 1: Polyester yarn, India",Calculations!$G$4:$G$21) -> 1428
A21: China | B21: =SUMIF(Calculations!$B$4:$B$21,"Cat 1: Cotton yarn, China",Calculations!$G$4:$G$21) -> 716.59 | C21: =SUMIF(Calculations!$B$4:$B$21,"Cat 1: Polyester yarn, China",Calculations!$G$4:$G$21) -> 999.6
A22: US | B22: =SUMIF(Calculations!$B$4:$B$21,"Cat 1: Cotton yarn, US",Calculations!$G$4:$G$21) -> 298.41 | C22: =SUMIF(Calculations!$B$4:$B$21,"Cat 1: Polyester yarn, US",Calculations!$G$4:$G$21) -> 428.4
